{
  try {
    runTest();
    isSucceeded=true;
  }
 catch (  Exception|AssertionError e) {
    testException=e;
  }
}
